2023-02-07 19:02:41,769 DEBUG    root            Loaded Command Group: ['gcloud', 'iam']
2023-02-07 19:02:41,770 DEBUG    root            Loaded Command Group: ['gcloud', 'iam', 'service_accounts']
2023-02-07 19:02:41,771 DEBUG    root            Loaded Command Group: ['gcloud', 'iam', 'service-accounts', 'create']
2023-02-07 19:02:41,773 DEBUG    root            Running [gcloud.iam.service-accounts.create] with arguments: [NAME: "dns01-solver"]
2023-02-07 19:02:41,779 DEBUG    urllib3.connectionpool Starting new HTTPS connection (1): iam.googleapis.com:443
2023-02-07 19:02:43,048 DEBUG    urllib3.connectionpool https://iam.googleapis.com:443 "POST /v1/projects/gke-app-376315/serviceAccounts?alt=json HTTP/1.1" 409 None
2023-02-07 19:02:43,050 DEBUG    root            Chosen display Format:default
2023-02-07 19:02:43,051 DEBUG    root            Chosen display Format:default
2023-02-07 19:02:43,051 DEBUG    root            Chosen display Format:default
2023-02-07 19:02:43,052 DEBUG    root            (gcloud.iam.service-accounts.create) Resource in projects [gke-app-376315] is the subject of a conflict: Service account dns01-solver already exists within project projects/gke-app-376315.
- '@type': type.googleapis.com/google.rpc.ResourceInfo
  resourceName: projects/gke-app-376315/serviceAccounts/dns01-solver@gke-app-376315.iam.gserviceaccount.com
Traceback (most recent call last):
  File "/tmp/google-cloud-sdk/lib/googlecloudsdk/calliope/cli.py", line 987, in Execute
    resources = calliope_command.Run(cli=self, args=args)
  File "/tmp/google-cloud-sdk/lib/googlecloudsdk/calliope/backend.py", line 807, in Run
    resources = command_instance.Run(args)
  File "/tmp/google-cloud-sdk/lib/surface/iam/service_accounts/create.py", line 74, in Run
    result = client.projects_serviceAccounts.Create(
  File "/tmp/google-cloud-sdk/lib/googlecloudsdk/generated_clients/apis/iam/v1/iam_v1_client.py", line 2260, in Create
    return self._RunMethod(
  File "/tmp/google-cloud-sdk/lib/third_party/apitools/base/py/base_api.py", line 737, in _RunMethod
    return self.ProcessHttpResponse(method_config, http_response, request)
  File "/tmp/google-cloud-sdk/lib/third_party/apitools/base/py/base_api.py", line 743, in ProcessHttpResponse
    self.__ProcessHttpResponse(method_config, http_response, request))
  File "/tmp/google-cloud-sdk/lib/third_party/apitools/base/py/base_api.py", line 609, in __ProcessHttpResponse
    raise exceptions.HttpError.FromResponse(
apitools.base.py.exceptions.HttpConflictError: HttpError accessing <https://iam.googleapis.com/v1/projects/gke-app-376315/serviceAccounts?alt=json>: response: <{'vary': 'Origin, X-Origin, Referer', 'content-type': 'application/json; charset=UTF-8', 'content-encoding': 'gzip', 'date': 'Tue, 07 Feb 2023 12:02:42 GMT', 'server': 'ESF', 'cache-control': 'private', 'x-xss-protection': '0', 'x-frame-options': 'SAMEORIGIN', 'x-content-type-options': 'nosniff', 'alt-svc': 'h3=":443"; ma=2592000,h3-29=":443"; ma=2592000', 'transfer-encoding': 'chunked', 'status': 409}>, content <{
  "error": {
    "code": 409,
    "message": "Service account dns01-solver already exists within project projects/gke-app-376315.",
    "status": "ALREADY_EXISTS",
    "details": [
      {
        "@type": "type.googleapis.com/google.rpc.ResourceInfo",
        "resourceName": "projects/gke-app-376315/serviceAccounts/dns01-solver@gke-app-376315.iam.gserviceaccount.com"
      }
    ]
  }
}
>
2023-02-07 19:02:43,066 ERROR    root            (gcloud.iam.service-accounts.create) Resource in projects [gke-app-376315] is the subject of a conflict: Service account dns01-solver already exists within project projects/gke-app-376315.
- '@type': type.googleapis.com/google.rpc.ResourceInfo
  resourceName: projects/gke-app-376315/serviceAccounts/dns01-solver@gke-app-376315.iam.gserviceaccount.com
2023-02-07 19:02:43,078 DEBUG    root            Metrics reporting process started...
